<?xml version="1.0" ?>
<!-- =================================================================================== -->
<!-- |    This document was autogenerated by xacro from /workdir/src/sjtu_drone_description/urdf/sjtu_drone_multi.urdf.xacro | -->
<!-- |    EDITING THIS FILE BY HAND IS NOT RECOMMENDED                                 | -->
<!-- =================================================================================== -->
<robot name="sjtu_drone">
  <link name="drone1/base_link">
    <inertial>
      <mass value="1.477"/>
      <origin rpy="0 0 0" xyz="0 0 0"/>
      <inertia ixx="0.1152" ixy="0" ixz="0" iyy="0.1152" iyz="0" izz="0.218"/>
    </inertial>
    <collision name="sjtu_drone_collision">
      <origin rpy="0 0 0" xyz="0   0   0.04"/>
      <geometry>
        <mesh filename="file:///workdir/install/sjtu_drone_description/share/sjtu_drone_description/models/sjtu_drone/quadrotor_4.stl"/>
        <!-- <mesh filename="package://sjtu_drone/quadrotor_4.stl"/> -->
      </geometry>
    </collision>
    <visual name="sjtu_drone_visual">
      <origin rpy="0 0 0" xyz="0   0   0.04"/>
      <geometry>
        <mesh filename="file:///workdir/install/sjtu_drone_description/share/sjtu_drone_description/models/sjtu_drone/quadrotor_4.dae"/>
        <!-- <mesh filename="package://sjtu_drone/quadrotor_4.dae"/> -->
      </geometry>
    </visual>
  </link>
  <!-- Front Camera Joint: Revolute on Y-axis -->
  <joint name="drone1/front_cam_joint" type="revolute">
    <origin rpy="0 0 0" xyz="0.2 0 0"/>
    <parent link="drone1/base_link"/>
    <child link="drone1/front_cam_link"/>
    <axis xyz="0 1 0"/>
    <limit effort="1.0" lower="-1.57" upper="1.57" velocity="1.0"/>
    <dynamics damping="0.1" friction="0.1"/>
    <ros2_control>
      <hardware>
        <plugin>fake_components/GenericSystem</plugin>
      </hardware>
      <command_interface name="position"/>
      <state_interface name="position"/>
      <state_interface name="velocity"/>
    </ros2_control>
  </joint>
  <link name="drone1/front_cam_link">
    <visual>
      <geometry>
        <cylinder length="0.1" radius="0.01"/>
      </geometry>
      <material name="Blue">
        <color rgba="0.0 0.0 1.0 1.0"/>
      </material>
    </visual>
    <collision>
      <geometry>
        <cylinder length="0.1" radius="0.01"/>
      </geometry>
    </collision>
    <inertial>
      <mass value="0.1"/>
      <inertia ixx="0.0001" ixy="0" ixz="0" iyy="0.0001" iyz="0" izz="0.0002"/>
    </inertial>
  </link>
  <gazebo>
    <plugin filename="libplugin_drone.so" name="simple_drone">
      <bodyName>drone1/base_link</bodyName>
      <rosNamespace>drone1</rosNamespace>
      <imuTopic>drone1/imu</imuTopic>
      <rollpitchProportionalGain>10.0</rollpitchProportionalGain>
      <rollpitchDifferentialGain>5.0</rollpitchDifferentialGain>
      <rollpitchLimit>1.5</rollpitchLimit>
      <yawProportionalGain>2.0</yawProportionalGain>
      <yawDifferentialGain>1.0</yawDifferentialGain>
      <yawLimit>20</yawLimit>
      <velocityXYProportionalGain>5.0</velocityXYProportionalGain>
      <velocityXYDifferentialGain>2.3</velocityXYDifferentialGain>
      <velocityXYLimit>30</velocityXYLimit>
      <velocityZProportionalGain>5.0</velocityZProportionalGain>
      <velocityZIntegralGain>0.0</velocityZIntegralGain>
      <velocityZDifferentialGain>1.0</velocityZDifferentialGain>
      <velocityZLimit>30</velocityZLimit>
      <positionXYProportionalGain>1.1</positionXYProportionalGain>
      <positionXYDifferentialGain>0.0</positionXYDifferentialGain>
      <positionXYIntegralGain>0.0</positionXYIntegralGain>
      <positionXYLimit>5</positionXYLimit>
      <positionZProportionalGain>1.0</positionZProportionalGain>
      <positionZDifferentialGain>0.2</positionZDifferentialGain>
      <positionZIntegralGain>0.0</positionZIntegralGain>
      <positionZLimit>-1</positionZLimit>
      <maxForce>300</maxForce>
      <motionSmallNoise>0.05</motionSmallNoise>
      <motionDriftNoise>0.03</motionDriftNoise>
      <motionDriftNoiseTime>5.0</motionDriftNoiseTime>
    </plugin>
  </gazebo>
  <gazebo>
    <plugin filename="libgazebo_ros_joint_state_publisher.so" name="gazebo_ros_joint_state_publisher">
      <joint_name>drone1/front_cam_joint</joint_name>
    </plugin>
  </gazebo>
  <!-- Sensors -->
  <!-- IMU sensor in 100fps -->
  <gazebo reference="drone1/base_link">
    <sensor name="sensor_imu" type="imu">
      <always_on> 1 </always_on>
      <visualize>1</visualize>
      <update_rate> 100 </update_rate>
      <pose> 0 0 0 0 0 0 </pose>
      <plugin filename="libgazebo_ros_imu_sensor.so" name="imu">
        <initial_orientation_as_reference>false</initial_orientation_as_reference>
      </plugin>
      <imu>
        <noise>
          <type>gaussian</type>
          <rate>
            <mean> 0 </mean>
            <stddev> 0 </stddev>
          </rate>
          <accel>
            <mean> 0 </mean>
            <stddev> 0.00 </stddev>
          </accel>
        </noise>
      </imu>
    </sensor>
  </gazebo>
  <!-- Front Camera Sensor -->
  <gazebo reference="drone1/front_cam_link">
    <sensor name="front_camera" type="camera">
      <camera>
        <horizontal_fov>2.09</horizontal_fov>
        <image>
          <width>960</width>
          <height>540</height>
          <format>R8G8B8</format>
        </image>
        <clip>
          <near>0.1</near>
          <far>100</far>
        </clip>
        <noise>
          <type>gaussian</type>
          <mean>0.0</mean>
          <stddev>0.005</stddev>
        </noise>
      </camera>
      <always_on>1</always_on>
      <update_rate>60</update_rate>
      <visualize>true</visualize>
      <plugin filename="libgazebo_ros_camera.so" name="camera_front">
        <ros>
          <remapping>image_raw:=camera_front</remapping>
          <remapping>camera_info:=camera_front_info</remapping>
        </ros>
        <camera_name>front</camera_name>
        <frame_name>front_cam_link</frame_name>
        <hack_baseline>0.07</hack_baseline>
      </plugin>
    </sensor>
  </gazebo>
</robot>
